Exception on /product [GET]
Traceback (most recent call last):
  File "/home/gokul/anaconda3/envs/muimui/lib/python3.7/site-packages/flask/app.py", line 1817, in wsgi_app
    response = self.full_dispatch_request()
  File "/home/gokul/anaconda3/envs/muimui/lib/python3.7/site-packages/flask/app.py", line 1477, in full_dispatch_request
    rv = self.handle_user_exception(e)
  File "/home/gokul/anaconda3/envs/muimui/lib/python3.7/site-packages/flask/app.py", line 1381, in handle_user_exception
    reraise(exc_type, exc_value, tb)
  File "/home/gokul/anaconda3/envs/muimui/lib/python3.7/site-packages/flask/_compat.py", line 33, in reraise
    raise value
  File "/home/gokul/anaconda3/envs/muimui/lib/python3.7/site-packages/flask/app.py", line 1475, in full_dispatch_request
    rv = self.dispatch_request()
  File "/home/gokul/anaconda3/envs/muimui/lib/python3.7/site-packages/flask/app.py", line 1461, in dispatch_request
    return self.view_functions[rule.endpoint](**req.view_args)
  File "/home/gokul/USFCA/MUIMUI/MUIMUI/src/webapp/app/views/main.py", line 69, in map
    import ipdb
AttributeError: 'SQLAlchemy' object has no attribute 'sessio'
